<?xml version="1.0"?>
<robot name="finger">

  <!-- ====================================
       Link: Base
       ==================================== -->
  <link name="base">
    <!-- Propiedades Visuales de la Base -->
    <visual>
      <origin xyz="0 0 0" rpy="0 0 0"/>
      <geometry>
        <box size="0.02 0.02 0.02"/>
      </geometry>
      <material name="grey">
        <color rgba="0.5 0.5 0.5 0.7"/>
      </material>
    </visual>
    <!-- Propiedades de Colisión de la Base -->
    <collision>
      <origin xyz="0 0 0" rpy="0 0 0"/>
      <geometry>
        <box size="0.02 0.02 0.02"/>
      </geometry>
    </collision>
  </link>

  <!-- ====================================
       Link: Proximal Phalanx Base (Intermedio)
       ==================================== -->
  <link name="proximal_phalanx_base">
    <!-- Propiedades Visuales de Proximal Phalanx Base -->
    <visual>
      <origin xyz="0 0 0" rpy="0 0 0"/>
      <geometry>
        <box size="0.005 0.005 0.005"/>
      </geometry>
      <material name="transparent">
        <color rgba="0 0 0 0"/>
      </material>
    </visual>
    <!-- Propiedades de Colisión de Proximal Phalanx Base -->
    <collision>
      <origin xyz="0 0 0" rpy="0 0 0"/>
      <geometry>
        <box size="0.005 0.005 0.005"/>
      </geometry>
    </collision>
  </link>

  <!-- Articulación: MCP_AbAd (Base a Proximal Phalanx Base) -->
  <joint name="MCP_AbAd" type="revolute"> 
    <parent link="base"/>
    <child link="proximal_phalanx_base"/>
    <origin xyz="0 0.01 0" rpy="0 0 0"/>
    <axis xyz="0 0 1"/> <!-- Eje Z para Abducción/Adducción -->
    <limit lower="0" upper="0" effort="10" velocity="0.5"/>
  </joint>

  <!-- ====================================
       Link: Proximal Phalanx
       ==================================== -->
  <link name="proximal_phalanx">
    <!-- Propiedades Inerciales de Proximal Phalanx -->
    <inertial>
      <origin xyz="0 0.015 0" rpy="0 0 0"/>
      <mass value="0.025133"/>
      <inertia ixx="1.0e-04" ixy="0" ixz="0" iyy="4.189e-04" iyz="0" izz="1.0e-04"/>
    </inertial>
    <!-- Propiedades Visuales de Proximal Phalanx -->
    <visual>
      <origin xyz="0 0.015 0" rpy="0 0 0"/>
      <geometry>
        <box size="0.014 0.03 0.014"/>
      </geometry>
      <material name="red">
        <color rgba="1 0 0 0.7"/>
      </material>
    </visual>
    <!-- Propiedades de Colisión de Proximal Phalanx -->
    <collision>
      <origin xyz="0 0.015 0" rpy="0 0 0"/>
      <geometry>
        <box size="0.014 0.03 0.014"/>
      </geometry>
    </collision>
  </link>

  <!-- Articulación: MCP_FlexExt (Proximal Phalanx Base a Proximal Phalanx) -->
  <joint name="MCP_FlexExt" type="revolute">
    <parent link="proximal_phalanx_base"/>
    <child link="proximal_phalanx"/>
    <origin xyz="0 0 0" rpy="0 0 0"/>
    <axis xyz="1 0 0"/> <!-- Eje X para Flexión/Extensión -->
    <limit lower="-0.73" upper="0.03" effort="10" velocity="0.4"/>
    <dynamics damping="0.1" friction="4.1"/> 
  </joint>

  <!-- ====================================
       Link: Middle Phalanx
       ==================================== -->
  <link name="middle_phalanx">
    <!-- Propiedades Inerciales de Middle Phalanx -->
    <inertial>
      <origin xyz="0 0.015 0" rpy="0 0 0"/>
      <mass value="0.022"/>
      <inertia ixx="1.0e-04" ixy="0" ixz="0" iyy="4.189e-04" iyz="0" izz="1.0e-04"/>
    </inertial>
    <!-- Propiedades Visuales de Middle Phalanx -->
    <visual>
      <origin xyz="0 0.015 0" rpy="0 0 0"/>
      <geometry>
        <box size="0.012 0.03 0.012"/>
      </geometry>
      <material name="green">
        <color rgba="0 1 0 0.7"/>
      </material>
    </visual>
    <!-- Propiedades de Colisión de Middle Phalanx -->
    <collision>
      <origin xyz="0 0.015 0" rpy="0 0 0"/>
      <geometry>
        <box size="0.012 0.03 0.012"/>
      </geometry>
    </collision>
  </link>

  <!-- Articulación: PIP (Proximal Phalanx a Middle Phalanx) -->
  <joint name="PIP" type="revolute">
    <parent link="proximal_phalanx"/>
    <child link="middle_phalanx"/>
    <origin xyz="0 0.03 0" rpy="0 0 0"/>
    <axis xyz="1 0 0"/>
    <limit lower="-0.88" upper="0.001" effort="10" velocity="0.4"/>
    <dynamics damping="0.1" friction="4.1"/> 
  </joint>

  <!-- ====================================
       Link: Distal Phalanx
       ==================================== -->
  <link name="distal_phalanx">
    <!-- Propiedades Inerciales de Distal Phalanx -->
    <inertial>
      <origin xyz="0 0.01 0" rpy="0 0 0"/>
      <mass value="0.018"/>
      <inertia ixx="1.0e-04" ixy="0" ixz="0" iyy="4.189e-04" iyz="0" izz="1.0e-04"/>
    </inertial>
    <!-- Propiedades Visuales de Distal Phalanx -->
    <visual>
      <origin xyz="0 0.01 0" rpy="0 0 0"/>
      <geometry>
        <box size="0.01 0.02 0.01"/>
      </geometry>
      <material name="blue">
        <color rgba="0 0 1 0.7"/>
      </material>
    </visual>
    <!-- Propiedades de Colisión de Distal Phalanx -->
    <collision>
      <origin xyz="0 0.01 0" rpy="0 0 0"/>
      <geometry>
        <box size="0.01 0.02 0.01"/>
      </geometry>
    </collision>
  </link>

  <!-- Articulación: DIP (Middle Phalanx a Distal Phalanx) -->
  <joint name="DIP" type="revolute">
    <parent link="middle_phalanx"/>
    <child link="distal_phalanx"/>
    <origin xyz="0 0.03 0" rpy="0 0 0"/>
    <axis xyz="1 0 0"/>
    <limit lower="-0.58" upper="0.001" effort="10" velocity="0.4"/>
    <dynamics damping="0.1" friction="4.1"/> 
  </joint>

</robot>